Workbook

Sheet Summary
A1: The Reserve at Royal Oak
A2: Development Pro Forma
A3: 1200 N Main St, Royal Oak, MI 48067
A4: Prepared by 1404 Labs — 2026-04-03
A6: PROJECT SNAPSHOT
A7: Property Type | B7: Multifamily
A8: Total Units | B8: 200
A9: Net Rentable SF | B9: 178000
A10: Lot Size (Acres) | B10: 4.2
A11: Construction Duration | B11: 20 months
A13: SOURCES & USES SUMMARY
A14: Total Development Cost | B14: ='Sources & Uses'!B30
A15: Land | B15: ='Sources & Uses'!B4
A16: Hard Costs | B16: ='Sources & Uses'!B10
A17: Soft Costs | B17: ='Sources & Uses'!B21
A18: Financing | B18: ='Sources & Uses'!B26
A19: Developer Fee | B19: ='Sources & Uses'!B28
A21: GP Equity | B21: ='Sources & Uses'!B35
A22: LP Equity | B22: ='Sources & Uses'!B36
A23: Senior Debt | B23: ='Sources & Uses'!B37
A25: KEY RETURN METRICS
A26: Yield on Cost (Year 1) | B26: ='NOI & Cash Flow'!B11
A27: Development Spread | B27: ='Waterfall'!B17
A28: Unlevered IRR | B28: ='Waterfall'!B14
A29: LP IRR | B29: ='Waterfall'!B15
A30: LP Equity Multiple | B30: ='Waterfall'!B16
A31: Cash-on-Cash (Year 1) | B31: ='NOI & Cash Flow'!B13
A32: DSCR (Year 1) | B32: ='NOI & Cash Flow'!B12
A33: Cost per Unit | B33: ='Sources & Uses'!B30/200
A34: Cost per SF | B34: ='Sources & Uses'!B30/178000

Sheet Assumptions
A1: Parameter | B1: Value | C1: Unit | D1: Source / Notes
A2: PROJECT IDENTIFICATION
A3: Project Name | B3: The Reserve at Royal Oak
A4: Property Address | B4: 1200 N Main St, Royal Oak, MI 48067
A5: Property Type | B5: multifamily
A6: Total Units | B6: 200 | C6: units
A7: Net Rentable SF | B7: 178000 | C7: SF
A8: Gross Buildable SF | B8: 209411.76 | C8: SF
A9: Lot Size | B9: 4.2 | C9: acres
A11: TIMELINE
A12: Construction Start | B12: 2026-09-01
A13: Construction Duration | B13: 20 | C13: months
A14: Lease-Up Duration | B14: 12 | C14: months
A15: Hold Period | B15: 5 | C15: years
A17: REVENUE ASSUMPTIONS
A18: Annual Rent Growth | B18: 0.03
A19: Vacancy Rate | B19: 0.05
A20: Loss to Lease | B20: 0.02
A21: Concession Months | B21: 1 | C21: months
A22: Bad Debt | B22: 0.01
A23: Other Income/Unit/Mo | B23: 125 | C23: $/unit/mo
A25: OPERATING EXPENSE ASSUMPTIONS
A26: Management Fee | B26: 0.03 | C26: % of EGI
A27: Payroll & Benefits | B27: 1100 | C27: $/unit/yr
A28: Repairs & Maintenance | B28: 600 | C28: $/unit/yr
A29: Turnover Costs | B29: 350 | C29: $/unit/yr
A30: Contract Services | B30: 250 | C30: $/unit/yr
A31: Water/Sewer | B31: 425 | C31: $/unit/yr
A32: Electric | B32: 240 | C32: $/unit/yr
A33: Gas | B33: 175 | C33: $/unit/yr
A34: Trash | B34: 200 | C34: $/unit/yr
A35: Insurance | B35: 525 | C35: $/unit/yr
A36: Real Estate Taxes | B36: 2200 | C36: $/unit/yr
A37: Admin/G&A | B37: 240 | C37: $/unit/yr
... A39: Replacement Reserves | B39: 250 | C39: $/unit/yr
A40: General Expense Growth | B40: 0.03
A41: Insurance Growth | B41: 0.07
A42: Tax Growth | B42: 0.03
A44: FINANCING ASSUMPTIONS
A45: Construction Loan LTC | B45: 0.65
...

Sheet Sources & Uses
A1: Line Item | B1: Amount | C1: $/Unit | D1: $/SF | E1: % of TDC
A2: USES OF FUNDS
A3: A. Land / Acquisition
A4: Land Purchase Price | B4: 5800000 | C4: =B4/200 | D4: =B4/178000 | E4: =IF(B30=0,0,B4/B30)
A6: B. Hard Costs
A7: Vertical Construction | B7: 36647059 | C7: =B7/200 | D7: =B7/178000 | E7: =IF(B30=0,0,B7/B30)
A8: Site Work | B8: 2800000 | C8: =B8/200 | D8: =B8/178000 | E8: =IF(B30=0,0,B8/B30)
A9: Hard Cost Contingency | B9: =(B7+B8)*0.07 | C9: =B9/200 | D9: =B9/178000 | E9: =IF(B30=0,0,B9/B30)
A10: Total Hard Costs | B10: =SUM(B7:B9) | C10: =B10/200 | D10: =B10/178000 | E10: =IF(B30=0,0,B10/B30)
A12: C. Soft Costs
A13: Architecture & Engineering | B13: 2800000 | C13: =B13/200 | D13: =B13/178000 | E13: =IF(B30=0,0,B13/B30)
A14: Permits & Impact Fees | B14: 1600000 | C14: =B14/200 | D14: =B14/178000 | E14: =IF(B30=0,0,B14/B30)
A15: Legal & Accounting | B15: 450000 | C15: =B15/200 | D15: =B15/178000 | E15: =IF(B30=0,0,B15/B30)
A16: Builder's Risk Insurance | B16: 380000 | C16: =B16/200 | D16: =B16/178000 | E16: =IF(B30=0,0,B16/B30)
A17: Marketing & Lease-Up | B17: 500000 | C17: =B17/200 | D17: =B17/178000 | E17: =IF(B30=0,0,B17/B30)
A18: Property Taxes During Construction | B18: 320000 | C18: =B18/200 | D18: =B18/178000 | E18: =IF(B30=0,0,B18/B30)
A19: Appraisal, Title & Survey | B19: 175000 | C19: =B19/200 | D19: =B19/178000 | E19: =IF(B30=0,0,B19/B30)
A20: Soft Cost Contingency | B20: =SUM(B13:B19)*0.05 | C20: =B20/200 | D20: =B20/178000 | E20: =IF(B30=0,0,B20/B30)
A21: Total Soft Costs | B21: =SUM(B13:B20) | C21: =B21/200 | D21: =B21/178000 | E21: =IF(B30=0,0,B21/B30)
A23: D. Financing Costs
A24: Loan Origination | B24: =B37*0.01 | C24: =B24/200 | D24: =B24/178000 | E24: =IF(B30=0,0,B24/B30)
A25: Capitalized Interest (est.) | B25: =B37*0.0725*0.5*20/12 | C25: =B25/200 | D25: =B25/178000 | E25: =IF(B30=0,0,B25/B30)
A26: Total Financing Costs | B26: =SUM(B24:B25) | C26: =B26/200 | D26: =B26/178000 | E26: =IF(B30=0,0,B26/B30)
A28: Developer Fee | B28: =(B4+B10+B21)*0.04 | C28: =B28/200 | D28: =B28/178000 | E28: =IF(B30=0,0,B28/B30)
A30: TOTAL DEVELOPMENT COST | B30: =B4+B10+B21+B26+B28 | C30: =B30/200 | D30: =B30/178000 | E30: =IF(B30=0,0,B30/B30)
A33: SOURCES OF FUNDS
A34: Source | B34: Amount | C34: % of Total | D34: Key Terms
A35: GP Equity | B35: =(B30-B37)*0.1 | C35: =IF(B30=0,0,B35/B30) | D35: 10% of equity
A36: LP Equity | B36: =(B30-B37)*0.9 | C36: =IF(B30=0,0,B36/B30) | D36: 90% of equity
A37: Construction Loan (Senior) | B37: =(0.65*(B4+B10+B21+B28))/(1-0.65*(0.01+0.0725*0.5*20/12)) | C37: =IF(B30=0,0,B37/B30) | D37: 65% LTC, 7.25%
A38: TOTAL SOURCES | B38: =B35+B36+B37 | C38: =IF(B30=0,0,B38/B30)
A40: Sources - Uses (must = 0) | B40: =B38-B30

Sheet Revenue
A1: Description | B1: Year 1 | C1: Year 2 | D1: Year 3 | E1: Year 4 | F1: Year 5
A2: UNIT MIX
A3: Unit Type | B3: Count | C3: Avg SF | D3: Rent/SF/Mo | E3: Rent/Unit/Mo | F3: Annual Rent
A4: Studio | B4: 24 | C4: 550 | D4: 3.1 | E4: =C4*D4 | F4: =B4*E4*12
A5: 1BR/1BA | B5: 80 | C5: 725 | D5: 2.95 | E5: =C5*D5 | F5: =B5*E5*12
A6: 2BR/2BA | B6: 72 | C6: 1050 | D6: 2.75 | E6: =C6*D6 | F6: =B6*E6*12
A7: 3BR/2BA | B7: 24 | C7: 1300 | D7: 2.55 | E7: =C7*D7 | F7: =B7*E7*12
A9: REVENUE PROJECTION
A10: Gross Potential Rent (GPR) | B10: =F4+F5+F6+F7 | C10: =B10*(1+0.03) | D10: =C10*(1+0.03) | E10: =D10*(1+0.03) | F10: =E10*(1+0.03)
A11: (-) Loss to Lease | B11: =-B10*0.02 | C11: =-C10*0.02 | D11: =-D10*0.02 | E11: =-E10*0.02 | F11: =-F10*0.02
A12: (-) Vacancy | B12: =-B10*0.05 | C12: =-C10*0.05 | D12: =-D10*0.05 | E12: =-E10*0.05 | F12: =-F10*0.05
A13: (-) Concessions | B13: =-B10*0.08333333333333333 | C13: =-C10*0.08333333333333333 | D13: =-D10*0.08333333333333333 | E13: =-E10*0.08333333333333333 | F13: =-F10*0.08333333333333333
A14: (-) Bad Debt | B14: =-B10*0.01 | C14: =-C10*0.01 | D14: =-D10*0.01 | E14: =-E10*0.01 | F14: =-F10*0.01
A15: Net Rental Income | B15: =B10+B11+B12+B13+B14 | C15: =C10+C11+C12+C13+C14 | D15: =D10+D11+D12+D13+D14 | E15: =E10+E11+E12+E13+E14 | F15: =F10+F11+F12+F13+F14
A16: (+) Other Income | B16: 300000 | C16: =B16*(1+0.03) | D16: =C16*(1+0.03) | E16: =D16*(1+0.03) | F16: =E16*(1+0.03)
A18: EFFECTIVE GROSS INCOME (EGI) | B18: =B15+B16 | C18: =C15+C16 | D18: =D15+D16 | E18: =E15+E16 | F18: =F15+F16

Sheet OpEx
A1: Expense Line Item | B1: $/Unit/Yr | C1: Year 1 | D1: Year 2 | E1: Year 3 | F1: Year 4 | G1: Year 5
A2: Management Fee | B2: 3.0% EGI | C2: ='Revenue'!B18*0.03 | D2: ='Revenue'!C18*0.03 | E2: ='Revenue'!D18*0.03 | F2: ='Revenue'!E18*0.03 | G2: ='Revenue'!F18*0.03
A3: Payroll & Benefits | B3: 1100 | C3: 220000 | D3: =C3*(1+0.03) | E3: =D3*(1+0.03) | F3: =E3*(1+0.03) | G3: =F3*(1+0.03)
A4: Repairs & Maintenance | B4: 600 | C4: 120000 | D4: =C4*(1+0.03) | E4: =D4*(1+0.03) | F4: =E4*(1+0.03) | G4: =F4*(1+0.03)
A5: Turnover Costs | B5: 350 | C5: 70000 | D5: =C5*(1+0.03) | E5: =D5*(1+0.03) | F5: =E5*(1+0.03) | G5: =F5*(1+0.03)
A6: Contract Services | B6: 250 | C6: 50000 | D6: =C6*(1+0.03) | E6: =D6*(1+0.03) | F6: =E6*(1+0.03) | G6: =F6*(1+0.03)
A7: Water / Sewer | B7: 425 | C7: 85000 | D7: =C7*(1+0.03) | E7: =D7*(1+0.03) | F7: =E7*(1+0.03) | G7: =F7*(1+0.03)
A8: Electric | B8: 240 | C8: 48000 | D8: =C8*(1+0.03) | E8: =D8*(1+0.03) | F8: =E8*(1+0.03) | G8: =F8*(1+0.03)
A9: Gas | B9: 175 | C9: 35000 | D9: =C9*(1+0.03) | E9: =D9*(1+0.03) | F9: =E9*(1+0.03) | G9: =F9*(1+0.03)
A10: Trash Removal | B10: 200 | C10: 40000 | D10: =C10*(1+0.03) | E10: =D10*(1+0.03) | F10: =E10*(1+0.03) | G10: =F10*(1+0.03)
A11: Insurance | B11: 525 | C11: 105000 | D11: =C11*(1+0.07) | E11: =D11*(1+0.07) | F11: =E11*(1+0.07) | G11: =F11*(1+0.07)
A12: Real Estate Taxes | B12: 2200 | C12: 440000 | D12: =C12*(1+0.03) | E12: =D12*(1+0.03) | F12: =E12*(1+0.03) | G12: =F12*(1+0.03)
A13: Admin / G&A | B13: 240 | C13: 48000 | D13: =C13*(1+0.03) | E13: =D13*(1+0.03) | F13: =E13*(1+0.03) | G13: =F13*(1+0.03)
A14: Marketing | B14: 150 | C14: 30000 | D14: =C14*(1+0.03) | E14: =D14*(1+0.03) | F14: =E14*(1+0.03) | G14: =F14*(1+0.03)
A15: Replacement Reserves | B15: 250 | C15: 50000 | D15: =C15*(1+0.03) | E15: =D15*(1+0.03) | F15: =E15*(1+0.03) | G15: =F15*(1+0.03)
A17: TOTAL OPERATING EXPENSES | C17: =C2+C3+C4+C5+C6+C7+C8+C9+C10+C11+C12+C13+C14+C15 | D17: =D2+D3+D4+D5+D6+D7+D8+D9+D10+D11+D12+D13+D14+D15 | E17: =E2+E3+E4+E5+E6+E7+E8+E9+E10+E11+E12+E13+E14+E15 | F17: =F2+F3+F4+F5+F6+F7+F8+F9+F10+F11+F12+F13+F14+F15 | G17: =G2+G3+G4+G5+G6+G7+G8+G9+G10+G11+G12+G13+G14+G15
A18: OpEx per Unit | C18: =C17/200 | D18: =D17/200 | E18: =E17/200 | F18: =F17/200 | G18: =G17/200
A19: OpEx Ratio (% of EGI) | C19: =IF('Revenue'!B18=0,0,C17/'Revenue'!B18) | D19: =IF('Revenue'!C18=0,0,D17/'Revenue'!C18) | E19: =IF('Revenue'!D18=0,0,E17/'Revenue'!D18) | F19: =IF('Revenue'!E18=0,0,F17/'Revenue'!E18) | G19: =IF('Revenue'!F18=0,0,G17/'Revenue'!F18)

Sheet NOI & Cash Flow
A1: Description | B1: Year 1 | C1: Year 2 | D1: Year 3 | E1: Year 4 | F1: Year 5
A2: Effective Gross Income | B2: ='Revenue'!B18 | C2: ='Revenue'!C18 | D2: ='Revenue'!D18 | E2: ='Revenue'!E18 | F2: ='Revenue'!F18
A3: (-) Operating Expenses | B3: =-'OpEx'!C17 | C3: =-'OpEx'!D17 | D3: =-'OpEx'!E17 | E3: =-'OpEx'!F17 | F3: =-'OpEx'!G17
A5: NET OPERATING INCOME (NOI) | B5: =B2+B3 | C5: =C2+C3 | D5: =D2+D3 | E5: =E2+E3 | F5: =F2+F3
A7: (-) Annual Debt Service | B7: =PMT(0.055/12,30*12,'Sources & Uses'!B30*0.65)*12 | C7: =PMT(0.055/12,30*12,'Sources & Uses'!B30*0.65)*12 | D7: =PMT(0.055/12,30*12,'Sources & Uses'!B30*0.65)*12 | E7: =PMT(0.055/12,30*12,'Sources & Uses'!B30*0.65)*12 | F7: =PMT(0.055/12,30*12,'Sources & Uses'!B30*0.65)*12
A8: BEFORE-TAX CASH FLOW (BTCF) | B8: =B5+B7 | C8: =C5+C7 | D8: =D5+D7 | E8: =E5+E7 | F8: =F5+F7
A10: KEY METRICS
A11: Yield on Cost | B11: =IF('Sources & Uses'!B30=0,0,B5/'Sources & Uses'!B30) | C11: =IF('Sources & Uses'!B30=0,0,C5/'Sources & Uses'!B30) | D11: =IF('Sources & Uses'!B30=0,0,D5/'Sources & Uses'!B30) | E11: =IF('Sources & Uses'!B30=0,0,E5/'Sources & Uses'!B30) | F11: =IF('Sources & Uses'!B30=0,0,F5/'Sources & Uses'!B30)
A12: DSCR | B12: =IF(B7=0,0,B5/ABS(B7)) | C12: =IF(C7=0,0,C5/ABS(C7)) | D12: =IF(D7=0,0,D5/ABS(D7)) | E12: =IF(E7=0,0,E5/ABS(E7)) | F12: =IF(F7=0,0,F5/ABS(F7))
A13: Cash-on-Cash Return | B13: =IF('Sources & Uses'!B35+'Sources & Uses'!B36=0,0,B8/('Sources & Uses'!B35+'Sources & Uses'!B36)) | C13: =IF('Sources & Uses'!B35+'Sources & Uses'!B36=0,0,C8/('Sources & Uses'!B35+'Sources & Uses'!B36)) | D13: =IF('Sources & Uses'!B35+'Sources & Uses'!B36=0,0,D8/('Sources & Uses'!B35+'Sources & Uses'!B36)) | E13: =IF('Sources & Uses'!B35+'Sources & Uses'!B36=0,0,E8/('Sources & Uses'!B35+'Sources & Uses'!B36)) | F13: =IF('Sources & Uses'!B35+'Sources & Uses'!B36=0,0,F8/('Sources & Uses'!B35+'Sources & Uses'!B36))
A15: DISPOSITION ANALYSIS
A16: Forward NOI (Year N+1) | B16: =F5*(1+0.03)
A17: Gross Sale Price | B17: =B16/0.0525
A18: (-) Disposition Costs | B18: =-B17*0.02
A19: NET SALE PROCEEDS | B19: =B17+B18
A20: Exit Cap Rate | B20: 0.0525

Sheet Waterfall
A1: Description | B1: Year 0 | C1: Year 1 | D1: Year 2 | E1: Year 3 | F1: Year 4 | G1: Year 5 | H1: Total
A2: CASH FLOWS
A3: Total Equity Invested | B3: =-('Sources & Uses'!B35+'Sources & Uses'!B36) | C3: 0 | D3: 0 | E3: 0 | F3: 0 | G3: 0 | H3: =SUM(B3:G3)
A4: Operating Cash Flow | B4: 0 | C4: ='NOI & Cash Flow'!B8 | D4: ='NOI & Cash Flow'!C8 | E4: ='NOI & Cash Flow'!D8 | F4: ='NOI & Cash Flow'!E8 | G4: ='NOI & Cash Flow'!F8 | H4: =SUM(B4:G4)
A5: Net Sale Proceeds | B5: 0 | C5: 0 | D5: 0 | E5: 0 | F5: 0 | G5: ='NOI & Cash Flow'!B19 | H5: =SUM(B5:G5)
A6: (-) Loan Payoff | B6: 0 | C6: 0 | D6: 0 | E6: 0 | F6: 0 | G6: =FV(0.055/12,5*12,PMT(0.055/12,30*12,('Sources & Uses'!B30*0.65)),('Sources & Uses'!B30*0.65)) | H6: =SUM(B6:G6)
A7: Total Cash Available | B7: =B3+B4+B5+B6 | C7: =C3+C4+C5+C6 | D7: =D3+D4+D5+D6 | E7: =E3+E4+E5+E6 | F7: =F3+F4+F5+F6 | G7: =G3+G4+G5+G6 | H7: =H3+H4+H5+H6
A9: LP DISTRIBUTIONS (90% equity, 8% pref)
A10: LP Distributions (pro-rata) | B10: =IF(B7<0,B7*0.9,MAX(0,B7)*0.9) | C10: =IF(C7<0,C7*0.9,MAX(0,C7)*0.9) | D10: =IF(D7<0,D7*0.9,MAX(0,D7)*0.9) | E10: =IF(E7<0,E7*0.9,MAX(0,E7)*0.9) | F10: =IF(F7<0,F7*0.9,MAX(0,F7)*0.9) | G10: =IF(G7<0,G7*0.9,MAX(0,G7)*0.9) | H10: =SUM(B10:G10)
A11: GP Distributions (pro-rata) | B11: =B7-B10 | C11: =C7-C10 | D11: =D7-D10 | E11: =E7-E10 | F11: =F7-F10 | G11: =G7-G10 | H11: =SUM(B11:G11)
A13: RETURN METRICS
A14: Unlevered IRR (Project) | B14: =IFERROR(IRR(B7:G7),"N/A")
A15: LP IRR | B15: =IFERROR(IRR(B10:G10),"N/A")
A16: LP Equity Multiple | B16: =IF('Sources & Uses'!B36=0,0,(SUMPRODUCT(MAX(B10:G10,0))/'Sources & Uses'!B36))
A17: Development Spread (YoC - Exit Cap) | B17: ='NOI & Cash Flow'!B11-'NOI & Cash Flow'!B20

Sheet Sensitivity
A1: SENSITIVITY ANALYSIS
A3: Table 1: Levered IRR by Exit Cap Rate × Rent Adjustment
A4: Note: Static scenario table. Formulas show base-case metrics; full DATA TABLE requires Excel's What-If → Data Table feature.
A6: Base Case Metrics
A7: Unlevered IRR | B7: ='Waterfall'!B14
A8: LP IRR | B8: ='Waterfall'!B15
A9: LP Equity Multiple | B9: ='Waterfall'!B16
A10: Yield on Cost (Year 1) | B10: ='NOI & Cash Flow'!B11
A11: Development Spread | B11: ='Waterfall'!B17
A12: DSCR (Year 1) | B12: ='NOI & Cash Flow'!B12
A13: Cash-on-Cash (Year 1) | B13: ='NOI & Cash Flow'!B13
A14: Total Development Cost | B14: ='Sources & Uses'!B30
A15: Cost per Unit | B15: ='Sources & Uses'!B30/200
A16: Net Sale Price | B16: ='NOI & Cash Flow'!B17
