Workbook

Sheet Dashboard
A1: Douglas Electric
A2: Manpower Loading Chart
A3: Report Date: 2026-04-07
A5: KEY METRICS
A6: Total Headcount (Week 1) | B6: ='Loading Chart'!C37
A7: Total Projects | B7: =COUNTA(A12:A17)
A8: Avg Utilization % | B8: =IF(C18=0,0,D18/C18)
A9: Over/Under-staffed Projects | B9: =COUNTIF(G12:G17,"Over-staffed")&" over / "&COUNTIF(G12:G17,"Under-staffed")&" under"
A10: PROJECT SUMMARY
A11: Project Name | B11: Status | C11: Total Planned Hours | D11: Total Actual Hours | E11: Variance | F11: Variance % | G11: Health
A12: Rivian Plant Phase 3 | B12: Active | C12: =SUM('Loading Chart'!C11:N11)*40 | D12: 4200 | E12: =C12-D12 | F12: =IF(C12=0,0,E12/C12) | G12: =IF(ABS(F12)<=0.05,"On Track",IF(F12>0,"Under-staffed","Over-staffed"))
A13: Mercy Hospital MRI Suite | B13: Active | C13: =SUM('Loading Chart'!C16:N16)*40 | D13: 1800 | E13: =C13-D13 | F13: =IF(C13=0,0,E13/C13) | G13: =IF(ABS(F13)<=0.05,"On Track",IF(F13>0,"Under-staffed","Over-staffed"))
A14: Target Store #4412 Remodel | B14: Active | C14: =SUM('Loading Chart'!C21:N21)*40 | D14: 960 | E14: =C14-D14 | F14: =IF(C14=0,0,E14/C14) | G14: =IF(ABS(F14)<=0.05,"On Track",IF(F14>0,"Under-staffed","Over-staffed"))
A15: Applebee's Service Call | B15: Winding Down | C15: =SUM('Loading Chart'!C26:N26)*40 | D15: 320 | E15: =C15-D15 | F15: =IF(C15=0,0,E15/C15) | G15: =IF(ABS(F15)<=0.05,"On Track",IF(F15>0,"Under-staffed","Over-staffed"))
A16: Data Center Build-Out | B16: Mobilizing | C16: =SUM('Loading Chart'!C31:N31)*40 | D16: 0 | E16: =C16-D16 | F16: =IF(C16=0,0,E16/C16) | G16: =IF(ABS(F16)<=0.05,"On Track",IF(F16>0,"Under-staffed","Over-staffed"))
A17: EV Charging Station - Walmart | B17: Mobilizing | C17: =SUM('Loading Chart'!C36:N36)*40 | D17: 0 | E17: =C17-D17 | F17: =IF(C17=0,0,E17/C17) | G17: =IF(ABS(F17)<=0.05,"On Track",IF(F17>0,"Under-staffed","Over-staffed"))
A18: TOTAL | C18: =SUM(C12:C17) | D18: =SUM(D12:D17) | E18: =C18-D18 | F18: =IF(C18=0,0,E18/C18)

Sheet Loading Chart
A1: Douglas Electric
A2: Manpower Loading Chart
A3: Report Date: 2026-04-07
A6: Project | B6: Class | C6: 2026-04-06 | D6: 2026-04-13 | E6: 2026-04-20 | F6: 2026-04-27 | G6: 2026-05-04 | H6: 2026-05-11 | I6: 2026-05-18 | J6: 2026-05-25 | K6: 2026-06-01 | L6: 2026-06-08 | M6: 2026-06-15 | N6: 2026-06-22
A7: Rivian Plant Phase 3 | B7: DE-2026-001
B8: JW | C8: 8 | D8: 8 | E8: 10 | F8: 10 | G8: 12 | H8: 12 | I8: 12 | J8: 14 | K8: 14 | L8: 14 | M8: 12 | N8: 10
B9: AP | C9: 6 | D9: 6 | E9: 8 | F9: 8 | G9: 10 | H9: 10 | I9: 10 | J9: 12 | K9: 12 | L9: 12 | M9: 10 | N9: 8
B10: FM | C10: 2 | D10: 2 | E10: 2 | F10: 2 | G10: 3 | H10: 3 | I10: 3 | J10: 3 | K10: 3 | L10: 3 | M10: 3 | N10: 2
B11: Total | C11: =SUM(C8:C10) | D11: =SUM(D8:D10) | E11: =SUM(E8:E10) | F11: =SUM(F8:F10) | G11: =SUM(G8:G10) | H11: =SUM(H8:H10) | I11: =SUM(I8:I10) | J11: =SUM(J8:J10) | ... N11: =SUM(N8:N10)
A12: Mercy Hospital MRI Suite | B12: DE-2026-002
B13: JW | C13: 4 | D13: 4 | E13: 4 | F13: 5 | G13: 5 | H13: 5 | I13: 4 | J13: 3 | K13: 2 | L13: 2 | M13: 1 | N13: 0
B14: AP | C14: 3 | D14: 3 | E14: 4 | F14: 4 | G14: 4 | H14: 4 | I14: 3 | J14: 2 | K14: 2 | L14: 1 | M14: 1 | N14: 0
B15: FM | C15: 1 | D15: 1 | E15: 1 | F15: 1 | G15: 1 | H15: 1 | I15: 1 | J15: 1 | K15: 1 | L15: 0 | M15: 0 | N15: 0
B16: Total | C16: =SUM(C13:C15) | D16: =SUM(D13:D15) | E16: =SUM(E13:E15) | F16: =SUM(F13:F15) | G16: =SUM(G13:G15) | H16: =SUM(H13:H15) | I16: =SUM(I13:I15) | J16: =SUM(J13:J15) | ... N16: =SUM(N13:N15)
A17: Target Store #4412 Remodel | B17: DE-2026-003
B18: JW | C18: 3 | D18: 3 | E18: 3 | F18: 3 | G18: 2 | H18: 2 | I18: 1 | J18: 0 | K18: 0 | L18: 0 | M18: 0 | N18: 0
B19: AP | C19: 2 | D19: 2 | E19: 2 | F19: 2 | G19: 2 | H19: 1 | I19: 1 | J19: 0 | K19: 0 | L19: 0 | M19: 0 | N19: 0
B20: FM | C20: 1 | D20: 1 | E20: 1 | F20: 1 | G20: 1 | H20: 0 | I20: 0 | J20: 0 | K20: 0 | L20: 0 | M20: 0 | N20: 0
B21: Total | C21: =SUM(C18:C20) | D21: =SUM(D18:D20) | E21: =SUM(E18:E20) | F21: =SUM(F18:F20) | G21: =SUM(G18:G20) | H21: =SUM(H18:H20) | I21: =SUM(I18:I20) | J21: =SUM(J18:J20) | ... N21: =SUM(N18:N20)
A22: Applebee's Service Call | B22: DE-2026-004
B23: JW | C23: 2 | D23: 1 | E23: 0 | F23: 0 | G23: 0 | H23: 0 | I23: 0 | J23: 0 | K23: 0 | L23: 0 | M23: 0 | N23: 0
B24: AP | C24: 0 | D24: 0 | E24: 0 | F24: 0 | G24: 0 | H24: 0 | I24: 0 | J24: 0 | K24: 0 | L24: 0 | M24: 0 | N24: 0
B25: FM | C25: 0 | D25: 0 | E25: 0 | F25: 0 | G25: 0 | H25: 0 | I25: 0 | J25: 0 | K25: 0 | L25: 0 | M25: 0 | N25: 0
B26: Total | C26: =SUM(C23:C25) | D26: =SUM(D23:D25) | E26: =SUM(E23:E25) | F26: =SUM(F23:F25) | G26: =SUM(G23:G25) | H26: =SUM(H23:H25) | I26: =SUM(I23:I25) | J26: =SUM(J23:J25) | ... N26: =SUM(N23:N25)
A27: Data Center Build-Out | B27: DE-2026-005
B28: JW | C28: 0 | D28: 0 | E28: 2 | F28: 4 | G28: 6 | H28: 8 | I28: 10 | J28: 10 | K28: 12 | L28: 12 | M28: 14 | N28: 14
B29: AP | C29: 0 | D29: 0 | E29: 1 | F29: 3 | G29: 5 | H29: 6 | I29: 8 | J29: 8 | K29: 10 | L29: 10 | M29: 12 | N29: 12
B30: FM | C30: 0 | D30: 0 | E30: 1 | F30: 1 | G30: 2 | H30: 2 | I30: 2 | J30: 2 | K30: 3 | L30: 3 | M30: 3 | N30: 3
B31: Total | C31: =SUM(C28:C30) | D31: =SUM(D28:D30) | E31: =SUM(E28:E30) | F31: =SUM(F28:F30) | G31: =SUM(G28:G30) | H31: =SUM(H28:H30) | I31: =SUM(I28:I30) | J31: =SUM(J28:J30) | ... N31: =SUM(N28:N30)
A32: EV Charging Station - Walmart | B32: DE-2026-006
B33: JW | C33: 0 | D33: 0 | E33: 0 | F33: 0 | G33: 2 | H33: 3 | I33: 3 | J33: 3 | K33: 3 | L33: 3 | M33: 2 | N33: 2
B34: AP | C34: 0 | D34: 0 | E34: 0 | F34: 0 | G34: 1 | H34: 2 | I34: 2 | J34: 2 | K34: 2 | L34: 2 | M34: 2 | N34: 2
B35: FM | C35: 0 | D35: 0 | E35: 0 | F35: 0 | G35: 1 | H35: 1 | I35: 1 | J35: 1 | K35: 1 | L35: 1 | M35: 1 | N35: 1
B36: Total | C36: =SUM(C33:C35) | D36: =SUM(D33:D35) | E36: =SUM(E33:E35) | F36: =SUM(F33:F35) | G36: =SUM(G33:G35) | H36: =SUM(H33:H35) | I36: =SUM(I33:I35) | J36: =SUM(J33:J35) | ... N36: =SUM(N33:N35)
A37: GRAND TOTAL | C37: =C11+C16+C21+C26+C31+C36 | D37: =D11+D16+D21+D26+D31+D36 | E37: =E11+E16+E21+E26+E31+E36 | F37: =F11+F16+F21+F26+F31+F36 | G37: =G11+G16+G21+G26+G31+G36 | H37: =H11+H16+H21+H26+H31+H36 | I37: =I11+I16+I21+I26+I31+I36 | J37: =J11+J16+J21+J26+J31+J36 | ... N37: =N11+N16+N21+N26+N31+N36
A39: CLASSIFICATION SUMMARY
A40: Journeyman | B40: JW | C40: =C8+C13+C18+C23+C28+C33 | D40: =D8+D13+D18+D23+D28+D33 | E40: =E8+E13+E18+E23+E28+E33 | F40: =F8+F13+F18+F23+F28+F33 | G40: =G8+G13+G18+G23+G28+G33 | H40: =H8+H13+H18+H23+H28+H33 | I40: =I8+I13+I18+I23+I28+I33 | J40: =J8+J13+J18+J23+J28+J33 | ... N40: =N8+N13+N18+N23+N28+N33
A41: Apprentice | B41: AP | C41: =C9+C14+C19+C24+C29+C34 | D41: =D9+D14+D19+D24+D29+D34 | E41: =E9+E14+E19+E24+E29+E34 | F41: =F9+F14+F19+F24+F29+F34 | G41: =G9+G14+G19+G24+G29+G34 | H41: =H9+H14+H19+H24+H29+H34 | I41: =I9+I14+I19+I24+I29+I34 | J41: =J9+J14+J19+J24+J29+J34 | ... N41: =N9+N14+N19+N24+N29+N34
A42: Foreman | B42: FM | C42: =C10+C15+C20+C25+C30+C35 | D42: =D10+D15+D20+D25+D30+D35 | E42: =E10+E15+E20+E25+E30+E35 | F42: =F10+F15+F20+F25+F30+F35 | G42: =G10+G15+G20+G25+G30+G35 | H42: =H10+H15+H20+H25+H30+H35 | I42: =I10+I15+I20+I25+I30+I35 | J42: =J10+J15+J20+J25+J30+J35 | ... N42: =N10+N15+N20+N25+N30+N35
A43: Grand Total | C43: =C37 | D43: =D37 | E43: =E37 | F43: =F37 | G43: =G37 | H43: =H37 | I43: =I37 | J43: =J37 | ... N43: =N37
...

Sheet Apprentice Ratio Monitor
A1: Douglas Electric
A2: Apprentice Ratio Monitor
A3: Report Date: 2026-04-07
A5: Project Name | B5: JW Count | C5: AP Count | D5: JW:AP Ratio | E5: Required Ratio | F5: Compliant
A6: Rivian Plant Phase 3 | B6: =SUM('Loading Chart'!C8:N8) | C6: =SUM('Loading Chart'!C9:N9) | D6: =IF(C6=0,0,B6/MAX(C6,1)) | E6: 1 | F6: =IF(C6=0,"N/A",IF(D6>=E6,"Y","N"))
A7: Mercy Hospital MRI Suite | B7: =SUM('Loading Chart'!C13:N13) | C7: =SUM('Loading Chart'!C14:N14) | D7: =IF(C7=0,0,B7/MAX(C7,1)) | E7: 1 | F7: =IF(C7=0,"N/A",IF(D7>=E7,"Y","N"))
A8: Target Store #4412 Remodel | B8: =SUM('Loading Chart'!C18:N18) | C8: =SUM('Loading Chart'!C19:N19) | D8: =IF(C8=0,0,B8/MAX(C8,1)) | E8: 1 | F8: =IF(C8=0,"N/A",IF(D8>=E8,"Y","N"))
A9: Applebee's Service Call | B9: =SUM('Loading Chart'!C23:N23) | C9: =SUM('Loading Chart'!C24:N24) | D9: =IF(C9=0,0,B9/MAX(C9,1)) | E9: 1 | F9: =IF(C9=0,"N/A",IF(D9>=E9,"Y","N"))
A10: Data Center Build-Out | B10: =SUM('Loading Chart'!C28:N28) | C10: =SUM('Loading Chart'!C29:N29) | D10: =IF(C10=0,0,B10/MAX(C10,1)) | E10: 1 | F10: =IF(C10=0,"N/A",IF(D10>=E10,"Y","N"))
A11: EV Charging Station - Walmart | B11: =SUM('Loading Chart'!C33:N33) | C11: =SUM('Loading Chart'!C34:N34) | D11: =IF(C11=0,0,B11/MAX(C11,1)) | E11: 1 | F11: =IF(C11=0,"N/A",IF(D11>=E11,"Y","N"))
A13: COMPLIANCE SUMMARY
A14: Total Compliant | B14: =COUNTIF(F6:F11,"Y")
A15: Total Non-Compliant | B15: =COUNTIF(F6:F11,"N")
A16: Compliance % | B16: =IF(COUNTA(F6:F11)=0,0,COUNTIF(F6:F11,"Y")/COUNTIFS(F6:F11,"<>N/A"))
