Workbook
Name TotalApplicants: 'Dashboard'!$B$8
Name HiredCount: 'Dashboard'!$B$11
Name ConversionRate: 'Dashboard'!$B$13

Sheet Dashboard
A1: Douglas Electric
A2: Recruiting Pipeline Dashboard
A3: As of 2026-04-09
A4: Prepared by 1404 Labs
A6: KEY METRICS
A7: Open Positions | B7: =COUNTIF('Open Positions'!P7:P12,"Open")
A8: Total Applicants | B8: =COUNTA('All Candidates'!A7:A24)
A9: In Interview | B9: =COUNTIF('All Candidates'!H7:H24,"Interview")+COUNTIF('All Candidates'!H7:H24,"Skills Test")
A10: Offers Extended | B10: =COUNTIF('All Candidates'!H7:H24,"Offer")
A11: Offers Accepted (Hired) | B11: =COUNTIF('All Candidates'!H7:H24,"Hired")
A12: Time to Hire (Avg Days) | B12: =IFERROR(AVERAGEIFS('All Candidates'!P7:P24,'All Candidates'!H7:H24,"Hired"),"N/A")
A13: Pipeline Conversion Rate | B13: =IF(COUNTA('All Candidates'!A7:A24)=0,0,COUNTIF('All Candidates'!H7:H24,"Hired")/COUNTA('All Candidates'!A7:A24))
A15: OPEN POSITIONS SUMMARY
A16: Position Title | B16: Classification | C16: Urgency | D16: Days Open | E16: Applicants | F16: In Interview | G16: Status
A17: ='Open Positions'!B7 | B17: ='Open Positions'!C7 | C17: ='Open Positions'!G7 | D17: ='Open Positions'!O7 | E17: ='Open Positions'!N7 | F17: =COUNTIFS('All Candidates'!B7:B24,A17,'All Candidates'!H7:H24,"Interview")+COUNTIFS('All Candidates'!B7:B24,A17,'All Candidates'!H7:H24,"Skills Test") | G17: ='Open Positions'!P7
A18: ='Open Positions'!B8 | B18: ='Open Positions'!C8 | C18: ='Open Positions'!G8 | D18: ='Open Positions'!O8 | E18: ='Open Positions'!N8 | F18: =COUNTIFS('All Candidates'!B7:B24,A18,'All Candidates'!H7:H24,"Interview")+COUNTIFS('All Candidates'!B7:B24,A18,'All Candidates'!H7:H24,"Skills Test") | G18: ='Open Positions'!P8
A19: ='Open Positions'!B9 | B19: ='Open Positions'!C9 | C19: ='Open Positions'!G9 | D19: ='Open Positions'!O9 | E19: ='Open Positions'!N9 | F19: =COUNTIFS('All Candidates'!B7:B24,A19,'All Candidates'!H7:H24,"Interview")+COUNTIFS('All Candidates'!B7:B24,A19,'All Candidates'!H7:H24,"Skills Test") | G19: ='Open Positions'!P9
A20: ='Open Positions'!B10 | B20: ='Open Positions'!C10 | C20: ='Open Positions'!G10 | D20: ='Open Positions'!O10 | E20: ='Open Positions'!N10 | F20: =COUNTIFS('All Candidates'!B7:B24,A20,'All Candidates'!H7:H24,"Interview")+COUNTIFS('All Candidates'!B7:B24,A20,'All Candidates'!H7:H24,"Skills Test") | G20: ='Open Positions'!P10
A21: ='Open Positions'!B11 | B21: ='Open Positions'!C11 | C21: ='Open Positions'!G11 | D21: ='Open Positions'!O11 | E21: ='Open Positions'!N11 | F21: =COUNTIFS('All Candidates'!B7:B24,A21,'All Candidates'!H7:H24,"Interview")+COUNTIFS('All Candidates'!B7:B24,A21,'All Candidates'!H7:H24,"Skills Test") | G21: ='Open Positions'!P11
A22: ='Open Positions'!B12 | B22: ='Open Positions'!C12 | C22: ='Open Positions'!G12 | D22: ='Open Positions'!O12 | E22: ='Open Positions'!N12 | F22: =COUNTIFS('All Candidates'!B7:B24,A22,'All Candidates'!H7:H24,"Interview")+COUNTIFS('All Candidates'!B7:B24,A22,'All Candidates'!H7:H24,"Skills Test") | G22: ='Open Positions'!P12
A24: SOURCE EFFECTIVENESS
A25: Source | B25: Applicants | C25: Hires | D25: Conversion Rate | E25: Monthly Cost | F25: Cost per Hire
A26: Company Website | B26: =COUNTIF('All Candidates'!D7:D24,A26) | C26: =COUNTIFS('All Candidates'!D7:D24,A26,'All Candidates'!H7:H24,"Hired") | D26: =IF(B26=0,0,C26/B26) | E26: 0 | F26: =IF(C26=0,"N/A",E26/C26)
A27: Indeed | B27: =COUNTIF('All Candidates'!D7:D24,A27) | C27: =COUNTIFS('All Candidates'!D7:D24,A27,'All Candidates'!H7:H24,"Hired") | D27: =IF(B27=0,0,C27/B27) | E27: 350 | F27: =IF(C27=0,"N/A",E27/C27)
A28: Job Fair | B28: =COUNTIF('All Candidates'!D7:D24,A28) | C28: =COUNTIFS('All Candidates'!D7:D24,A28,'All Candidates'!H7:H24,"Hired") | D28: =IF(B28=0,0,C28/B28) | E28: 500 | F28: =IF(C28=0,"N/A",E28/C28)
A29: Referral | B29: =COUNTIF('All Candidates'!D7:D24,A29) | C29: =COUNTIFS('All Candidates'!D7:D24,A29,'All Candidates'!H7:H24,"Hired") | D29: =IF(B29=0,0,C29/B29) | E29: 0 | F29: =IF(C29=0,"N/A",E29/C29)
A30: Social Media | B30: =COUNTIF('All Candidates'!D7:D24,A30) | C30: =COUNTIFS('All Candidates'!D7:D24,A30,'All Candidates'!H7:H24,"Hired") | D30: =IF(B30=0,0,C30/B30) | E30: 50 | F30: =IF(C30=0,"N/A",E30/C30)
A31: Trade School | B31: =COUNTIF('All Candidates'!D7:D24,A31) | C31: =COUNTIFS('All Candidates'!D7:D24,A31,'All Candidates'!H7:H24,"Hired") | D31: =IF(B31=0,0,C31/B31) | E31: 0 | F31: =IF(C31=0,"N/A",E31/C31)
A32: Union Hall | B32: =COUNTIF('All Candidates'!D7:D24,A32) | C32: =COUNTIFS('All Candidates'!D7:D24,A32,'All Candidates'!H7:H24,"Hired") | D32: =IF(B32=0,0,C32/B32) | E32: 0 | F32: =IF(C32=0,"N/A",E32/C32)
A33: Walk-in | B33: =COUNTIF('All Candidates'!D7:D24,A33) | C33: =COUNTIFS('All Candidates'!D7:D24,A33,'All Candidates'!H7:H24,"Hired") | D33: =IF(B33=0,0,C33/B33) | E33: 0 | F33: =IF(C33=0,"N/A",E33/C33)
A34: TOTAL | B34: =SUM(B26:B33) | C34: =SUM(C26:C33) | D34: =IF(B34=0,0,C34/B34) | E34: =SUM(E26:E33) | F34: =IF(C34=0,"N/A",E34/C34)
A36: CANDIDATES BY STATUS
A37: Status | B37: Count
A38: New | B38: =COUNTIF('All Candidates'!H7:H24,A38)
A39: Screening | B39: =COUNTIF('All Candidates'!H7:H24,A39)
A40: Phone Screen | B40: =COUNTIF('All Candidates'!H7:H24,A40)
A41: Interview | B41: =COUNTIF('All Candidates'!H7:H24,A41)
A42: Skills Test | B42: =COUNTIF('All Candidates'!H7:H24,A42)
A43: Offer | B43: =COUNTIF('All Candidates'!H7:H24,A43)
A44: Hired | B44: =COUNTIF('All Candidates'!H7:H24,A44)
...

Sheet All Candidates
A1: Douglas Electric
A2: Recruiting Pipeline -- All Candidates
A3: As of 2026-04-09
A4: Prepared by 1404 Labs
A6: Candidate Name | B6: Position Applied | C6: Classification | D6: Source | E6: Date Applied | F6: Phone | G6: Email | H6: Status | I6: Interview Date | J6: Interviewer | K6: Skills Test Score | L6: Offered Rate ($/hr) | M6: Market Rate ($/hr) | N6: Rate vs Market | O6: Start Date | P6: Days in Pipeline | Q6: Notes
A7: James Whitfield | B7: Journeyman Wireman | C7: JW | D7: Indeed | E7: 46096 | F7: (313) 555-0142 | G7: jwhitfield@email.com | H7: Interview | I7: 46114 | J7: Mike Torres | M7: 42 | N7: =IF(OR(L7="",L7=0,M7="",M7=0),"",(L7-M7)/M7) | P7: =IF(E7="","",INT(TODAY()-E7)) | Q7: 8 years commercial experience, strong conduit skills
A8: Marcus Reed | B8: Journeyman Wireman | C8: JW | D8: Referral | E8: 46101 | F8: (248) 555-0198 | G8: mreed77@email.com | H8: Skills Test | I8: 46109 | J8: Mike Torres | K8: 88 | M8: 42 | N8: =IF(OR(L8="",L8=0,M8="",M8=0),"",(L8-M8)/M8) | P8: =IF(E8="","",INT(TODAY()-E8)) | Q8: Currently at Sackett Electric. Looking for better benefits.
A9: David Okonkwo | B9: Journeyman Wireman | C9: JW | D9: Indeed | E9: 46113 | F9: (734) 555-0267 | G9: dokonkwo@email.com | H9: Phone Screen | M9: 42 | N9: =IF(OR(L9="",L9=0,M9="",M9=0),"",(L9-M9)/M9) | P9: =IF(E9="","",INT(TODAY()-E9)) | Q9: 6 years experience, IBEW card
A10: Carlos Mendez | B10: Foreman | C10: Foreman | D10: Referral | E10: 46081 | F10: (313) 555-0334 | G10: cmendez@email.com | H10: Offer | I10: 46091 | J10: Dave Kowalski | K10: 92 | L10: 52 | M10: 52 | N10: =IF(OR(L10="",L10=0,M10="",M10=0),"",(L10-M10)/M10) | P10: =IF(E10="","",INT(TODAY()-E10)) | Q10: 12 years industrial, managed crews of 15+. Offer extended 4/5.
A11: Ryan O'Malley | B11: 3rd Year Apprentice | C11: Apprentice | D11: Trade School | E11: 46106 | F11: (248) 555-0412 | G11: romalley@email.com | H11: Interview | I11: 46120 | J11: Mike Torres | M11: 24 | N11: =IF(OR(L11="",L11=0,M11="",M11=0),"",(L11-M11)/M11) | P11: =IF(E11="","",INT(TODAY()-E11)) | Q11: JATC 3rd year, strong classroom performance
A12: Tyler Brooks | B12: Journeyman Wireman | C12: JW | D12: Indeed | E12: 46086 | F12: (586) 555-0178 | G12: tbrooks@email.com | H12: Rejected | I12: 46099 | J12: Mike Torres | K12: 45 | M12: 42 | N12: =IF(OR(L12="",L12=0,M12="",M12=0),"",(L12-M12)/M12) | P12: =IF(E12="","",INT(TODAY()-E12)) | Q12: Failed skills test -- weak on NEC code knowledge
A13: Anthony Russo | B13: Fire Alarm Tech | C13: Fire Alarm Tech | D13: Indeed | E13: 46115 | F13: (734) 555-0521 | G13: arusso@email.com | H13: New | M13: 38 | N13: =IF(OR(L13="",L13=0,M13="",M13=0),"",(L13-M13)/M13) | P13: =IF(E13="","",INT(TODAY()-E13)) | Q13: NICET II certified, 4 years at SimplexGrinnell
A14: Brandon Hayes | B14: Helper/Pre-Apprentice | C14: Helper | D14: Walk-in | E14: 46119 | F14: (313) 555-0689 | H14: New | M14: 18 | N14: =IF(OR(L14="",L14=0,M14="",M14=0),"",(L14-M14)/M14) | P14: =IF(E14="","",INT(TODAY()-E14)) | Q14: No experience, eager to learn. Heard about us from job site sign.
A15: Kevin Park | B15: 3rd Year Apprentice | C15: Apprentice | D15: Trade School | E15: 46109 | F15: (248) 555-0745 | G15: kpark@email.com | H15: Phone Screen | M15: 24 | N15: =IF(OR(L15="",L15=0,M15="",M15=0),"",(L15-M15)/M15) | P15: =IF(E15="","",INT(TODAY()-E15)) | Q15: Southeastern Michigan JATC referral
A16: Jerome Washington | B16: Foreman | C16: Foreman | D16: Referral | E16: 46082 | F16: (313) 555-0856 | G16: jwash@email.com | H16: Rejected | I16: 46093 | J16: Dave Kowalski | K16: 65 | M16: 52 | N16: =IF(OR(L16="",L16=0,M16="",M16=0),"",(L16-M16)/M16) | P16: =IF(E16="","",INT(TODAY()-E16)) | Q16: Good people skills but insufficient industrial experience
A17: Derek Simmons | B17: Journeyman Wireman | C17: JW | D17: Job Fair | E17: 46103 | F17: (248) 555-0913 | G17: dsimmons@email.com | H17: Interview | I17: 46122 | J17: Mike Torres | M17: 42 | N17: =IF(OR(L17="",L17=0,M17="",M17=0),"",(L17-M17)/M17) | P17: =IF(E17="","",INT(TODAY()-E17)) | Q17: Met at skilled trades career fair. 5 years residential, transitioning to commercial.
A18: Nathan Volkov | B18: Journeyman Wireman | C18: JW | D18: Referral | E18: 46063 | F18: (734) 555-1047 | G18: nvolkov@email.com | H18: Hired | I18: 46073 | J18: Mike Torres | K18: 91 | L18: 43 | M18: 42 | N18: =IF(OR(L18="",L18=0,M18="",M18=0),"",(L18-M18)/M18) | O18: 46084 | P18: =IF(E18="","",INT(TODAY()-E18)) | Q18: Excellent hire. 10 years commercial, OSHA 30, NFPA 70E.
A19: Amir Patel | B19: 3rd Year Apprentice | C19: Apprentice | D19: Trade School | E19: 46037 | F19: (248) 555-1123 | G19: apatel@email.com | H19: Hired | I19: 46047 | J19: Mike Torres | K19: 82 | L19: 24 | M19: 24 | N19: =IF(OR(L19="",L19=0,M19="",M19=0),"",(L19-M19)/M19) | O19: 46063 | P19: =IF(E19="","",INT(TODAY()-E19)) | Q19: JATC top of class. Started Feb 10.
A20: Chris Donovan | B20: Foreman | C20: Foreman | D20: Indeed | E20: 46117 | F20: (586) 555-1234 | G20: cdonovan@email.com | H20: New | M20: 52 | N20: =IF(OR(L20="",L20=0,M20="",M20=0),"",(L20-M20)/M20) | P20: =IF(E20="","",INT(TODAY()-E20)) | Q20: 15 years industrial, currently employed at Motor City Electric
A21: Sean Murphy | B21: Fire Alarm Tech | C21: Fire Alarm Tech | D21: Job Fair | E21: 46103 | F21: (248) 555-1367 | G21: smurphy@email.com | H21: Phone Screen | M21: 38 | N21: =IF(OR(L21="",L21=0,M21="",M21=0),"",(L21-M21)/M21) | P21: =IF(E21="","",INT(TODAY()-E21)) | Q21: NICET I, working toward Level II. 2 years experience.
A22: Luis Ramirez | B22: Helper/Pre-Apprentice | C22: Helper | D22: Walk-in | E22: 46120 | F22: (313) 555-1489 | H22: New | M22: 18 | N22: =IF(OR(L22="",L22=0,M22="",M22=0),"",(L22-M22)/M22) | P22: =IF(E22="","",INT(TODAY()-E22)) | Q22: Construction laborer background, wants to get into electrical
A23: Jake Patterson | B23: Journeyman Wireman | C23: JW | D23: Social Media | E23: 46111 | F23: (586) 555-1590 | G23: jpatt@email.com | H23: Withdrew | M23: 42 | N23: =IF(OR(L23="",L23=0,M23="",M23=0),"",(L23-M23)/M23) | P23: =IF(E23="","",INT(TODAY()-E23)) | Q23: Withdrew -- accepted position elsewhere before phone screen
A24: Tommy Nguyen | B24: Journeyman Wireman | C24: JW | D24: Referral | E24: 46099 | F24: (734) 555-1678 | G24: tnguyen@email.com | H24: Skills Test | I24: 46107 | J24: Mike Torres | K24: 78 | M24: 42 | N24: =IF(OR(L24="",L24=0,M24="",M24=0),"",(L24-M24)/M24) | P24: =IF(E24="","",INT(TODAY()-E24)) | Q24: 7 years experience. Good interview, scheduling ride-along.
A25: TOTAL: 18 Candidates

Sheet Open Positions
A1: Douglas Electric
A2: Recruiting Pipeline -- Open Positions
A3: As of 2026-04-09
A4: Prepared by 1404 Labs
A6: Position ID | B6: Title | C6: Classification | D6: Department/Team | E6: Hiring Manager | F6: Date Opened | G6: Urgency | H6: Required Certs | I6: Min Yrs Exp | J6: Wage Low ($/hr) | K6: Wage High ($/hr) | L6: Market Rate ($/hr) | M6: Wage Competitiveness | N6: # Applicants | O6: Days Open | P6: Status
A7: POS-001 | B7: Journeyman Wireman | C7: JW | D7: Commercial | E7: Mike Torres | F7: 46068 | G7: Critical | H7: State Journeyman License, OSHA 30, NFPA 70E | I7: 4 | J7: 38 | K7: 45 | L7: 42 | M7: =IF(OR(L7=0,L7=""),"N/A",IF(K7<L7,"Below Market",IF(J7>L7,"Above Market","Competitive"))) | N7: =COUNTIF('All Candidates'!B7:B24,B7) | O7: =IF(F7="","",INT(TODAY()-F7)) | P7: Open
A8: POS-002 | B8: Journeyman Wireman | C8: JW | D8: Commercial | E8: Mike Torres | F8: 46082 | G8: Critical | H8: State Journeyman License, OSHA 10 | I8: 4 | J8: 38 | K8: 45 | L8: 42 | M8: =IF(OR(L8=0,L8=""),"N/A",IF(K8<L8,"Below Market",IF(J8>L8,"Above Market","Competitive"))) | N8: =COUNTIF('All Candidates'!B7:B24,B8) | O8: =IF(F8="","",INT(TODAY()-F8)) | P8: Open
A9: POS-003 | B9: 3rd Year Apprentice | C9: Apprentice | D9: Commercial | E9: Mike Torres | F9: 46091 | G9: High | H9: OSHA 10 | I9: 2 | J9: 22 | K9: 26 | L9: 24 | M9: =IF(OR(L9=0,L9=""),"N/A",IF(K9<L9,"Below Market",IF(J9>L9,"Above Market","Competitive"))) | N9: =COUNTIF('All Candidates'!B7:B24,B9) | O9: =IF(F9="","",INT(TODAY()-F9)) | P9: Open
A10: POS-004 | B10: Foreman | C10: Foreman | D10: Industrial | E10: Dave Kowalski | F10: 46042 | G10: Critical | H10: State Journeyman License, OSHA 30, NFPA 70E, First Aid/CPR | I10: 8 | J10: 48 | K10: 55 | L10: 52 | M10: =IF(OR(L10=0,L10=""),"N/A",IF(K10<L10,"Below Market",IF(J10>L10,"Above Market","Competitive"))) | N10: =COUNTIF('All Candidates'!B7:B24,B10) | O10: =IF(F10="","",INT(TODAY()-F10)) | P10: Open
A11: POS-005 | B11: Fire Alarm Tech | C11: Fire Alarm Tech | D11: Service | E11: Lisa Chen | F11: 46101 | G11: Medium | H11: OSHA 10, NICET Level II | I11: 3 | J11: 35 | K11: 42 | L11: 38 | M11: =IF(OR(L11=0,L11=""),"N/A",IF(K11<L11,"Below Market",IF(J11>L11,"Above Market","Competitive"))) | N11: =COUNTIF('All Candidates'!B7:B24,B11) | O11: =IF(F11="","",INT(TODAY()-F11)) | P11: Open
A12: POS-006 | B12: Helper/Pre-Apprentice | C12: Helper | E12: Mike Torres | F12: 46113 | G12: Low | I12: 0 | J12: 18 | K12: 20 | L12: 18 | M12: =IF(OR(L12=0,L12=""),"N/A",IF(K12<L12,"Below Market",IF(J12>L12,"Above Market","Competitive"))) | N12: =COUNTIF('All Candidates'!B7:B24,B12) | O12: =IF(F12="","",INT(TODAY()-F12)) | P12: Open
A13: TOTAL: 6 Positions | N13: =SUM(N7:N12)
